Workbook
Name IQ_CH: 110000
Name IQ_CQ: 5000
Name IQ_CY: 10000
Name IQ_DAILY: 500000
Name IQ_FH: 100000
Name IQ_FQ: 500
Name IQ_FY: 1000
Name IQ_LTM: 2000
Name IQ_MONTH: 15000
Name IQ_NTM: 6000
Name IQ_WEEK: 50000
Name IQ_YTD: 3000
Name UPDATE: 'Data Sheet'!$E$1

Sheet Cover

Sheet Assumptions
C3: 2026 | D3: =C3+1 -> 2027 | E3: =D3+1 -> 2028 | F3: =E3+1 -> 2029 | G3: =F3+1 -> 2030
B5: Revenue Growth % | C5: 0.25 | D5: 0.22 | E5: 0.15 | F5: 0.18 | G5: 0.12
B6: COGS (% of Revenue) | C6: 0.952 | D6: 0.95 | E6: 0.948 | F6: 0.947 | G6: 0.945
B8: EBITDA % | C8: 0.045 | D8: 0.05 | E8: 0.059 | F8: 0.068 | G8: 0.075
B10: Tax Rate | C10: 0.25 | D10: 0.25 | E10: 0.25 | F10: 0.25 | G10: 0.25
B12: Depreciation (% of Revenue) | C12: 0.008 | D12: 0.008 | E12: 0.008 | F12: 0.008 | G12: 0.008
B13: Capex (% of Revenue) | C13: 0.02 | D13: 0.018 | E13: 0.015 | F13: 0.013 | G13: 0.012
B15: Receivable Days | C15: 57 | D15: 54 | E15: 50 | F15: 47 | G15: 44
B16: Inventory Days | C16: 39 | D16: 39 | E16: 38 | F16: 38 | G16: 38
B21: Risk Free Rate | C21: 0.07
B22: Market Return | C22: 0.13
B23: Beta | C23: 1.15
B24: Cost of Debt | C24: 0.09
B25: Debt/(Equity + Debt) | C25: 0.2
B26: Equity/(Equity + Debt) | C26: =1-C25 -> 0.8
B27: WACC | C27: =(C21+(C22-C21)*C23)*C26+(C24*C25*(1-C10)) -> 0.1247
B29: Terminal Growth (g) | C29: 0.06

Sheet HistoricalFS
B2: ="Historical Financial Statement - "&'Data Sheet'!B1 -> Historical Financial Statement - DIXON TECHNOLOGIES (INDIA) LTD
B3: Years | C3: ='Data Sheet'!F16 -> 43921 | D3: ='Data Sheet'!G16 -> 44286 | E3: ='Data Sheet'!H16 -> 44651 | F3: ='Data Sheet'!I16 -> 45016 | G3: ='Data Sheet'!J16 -> 45382 | H3: ='Data Sheet'!K16 -> 45747
A5: # | B5: Income Statement
B6: Sales | C6: =IFERROR('Data Sheet'!F17,0) -> 4400.12 | D6: =IFERROR('Data Sheet'!G17,0) -> 6448.17 | E6: =IFERROR('Data Sheet'!H17,0) -> 10697.08 | F6: =IFERROR('Data Sheet'!I17,0) -> 12192.01 | G6: =IFERROR('Data Sheet'!J17,0) -> 17690.9 | H6: =IFERROR('Data Sheet'!K17,0) -> 38860.1
B7: Sales Growth | C7: =IFERROR(C6/#REF!-1, 0) -> 0 | D7: =IFERROR(D6/C6-1, 0) -> 0.46545321 | E7: =IFERROR(E6/D6-1, 0) -> 0.65893269 | F7: =IFERROR(F6/E6-1, 0) -> 0.13975122 | G7: =IFERROR(G6/F6-1, 0) -> 0.45102407 | H7: =IFERROR(H6/G6-1, 0) -> 1.1966152
B9: COGS | C9: =IFERROR(SUM('Data Sheet'!F18,'Data Sheet'!F20:F22)-1*'Data Sheet'!F19,0) -> 4119.71 | D9: =IFERROR(SUM('Data Sheet'!G18,'Data Sheet'!G20:G22)-1*'Data Sheet'!G19,0) -> 6082.95 | E9: =IFERROR(SUM('Data Sheet'!H18,'Data Sheet'!H20:H22)-1*'Data Sheet'!H19,0) -> 10225.37 | F9: =IFERROR(SUM('Data Sheet'!I18,'Data Sheet'!I20:I22)-1*'Data Sheet'!I19,0) -> 11566.32 | G9: =IFERROR(SUM('Data Sheet'!J18,'Data Sheet'!J20:J22)-1*'Data Sheet'!J19,0) -> 16854.72 | H9: =IFERROR(SUM('Data Sheet'!K18,'Data Sheet'!K20:K22)-1*'Data Sheet'!K19,0) -> 37116.31
B10: COGS % Sales | C10: =IFERROR(C9/C6, 0) -> 0.93627219 | D10: =IFERROR(D9/D6, 0) -> 0.94336067 | E10: =IFERROR(E9/E6, 0) -> 0.95590292 | F10: =IFERROR(F9/F6, 0) -> 0.94868032 | G10: =IFERROR(G9/G6, 0) -> 0.95273389 | H10: =IFERROR(H9/H6, 0) -> 0.95512647
B12: Gross Profit | C12: =C6-C9 -> 280.41 | D12: =D6-D9 -> 365.22 | E12: =E6-E9 -> 471.71 | F12: =F6-F9 -> 625.69 | G12: =G6-G9 -> 836.18 | H12: =H6-H9 -> 1743.79
B13: Gross Margins | C13: =IFERROR(C12/C6,0) -> 0.063727807 | D13: =IFERROR(D12/D6,0) -> 0.056639326 | E13: =IFERROR(E12/E6,0) -> 0.044097081 | F13: =IFERROR(F12/F6,0) -> 0.051319676 | G13: =IFERROR(G12/G6,0) -> 0.047266109 | H13: =IFERROR(H12/H6,0) -> 0.044873534
B15: Selling & General Expenses | C15: =IFERROR(SUM('Data Sheet'!F23:F24),0) -> 52.58 | D15: =IFERROR(SUM('Data Sheet'!G23:G24),0) -> 73.02 | E15: =IFERROR(SUM('Data Sheet'!H23:H24),0) -> 87.41 | F15: =IFERROR(SUM('Data Sheet'!I23:I24),0) -> 106.24 | G15: =IFERROR(SUM('Data Sheet'!J23:J24),0) -> 131.13 | H15: =IFERROR(SUM('Data Sheet'!K23:K24),0) -> 228.94
B16: S&G Exp % Sales | C16: =IFERROR(C15/C6,0) -> 0.011949674 | D16: =IFERROR(D15/D6,0) -> 0.011324143 | E16: =IFERROR(E15/E6,0) -> 0.0081713888 | F16: =IFERROR(F15/F6,0) -> 0.0087139036 | G16: =IFERROR(G15/G6,0) -> 0.0074122854 | H16: =IFERROR(H15/H6,0) -> 0.0058913899
B18: EBITDA (Operational) | C18: =IFERROR(C12-C15,0) -> 227.83 | D18: =IFERROR(D12-D15,0) -> 292.2 | E18: =IFERROR(E12-E15,0) -> 384.3 | F18: =IFERROR(F12-F15,0) -> 519.45 | G18: =IFERROR(G12-G15,0) -> 705.05 | H18: =IFERROR(H12-H15,0) -> 1514.85
B19: EBITDA Margins | C19: =IFERROR(C18/C6,0) -> 0.051778133 | D19: =IFERROR(D18/D6,0) -> 0.045315182 | E19: =IFERROR(E18/E6,0) -> 0.035925692 | F19: =IFERROR(F18/F6,0) -> 0.042605772 | G19: =IFERROR(G18/G6,0) -> 0.039853823 | H19: =IFERROR(H18/H6,0) -> 0.038982144
B20: EBITDA (Screener) | C20: =IFERROR('Data Sheet'!F34,0) -> 232.74 | D20: =IFERROR('Data Sheet'!G34,0) -> 293.45 | E20: =IFERROR('Data Sheet'!H34,0) -> 387.9 | F20: =IFERROR('Data Sheet'!I34,0) -> 523.92 | G20: =IFERROR('Data Sheet'!J34,0) -> 729.5 | H20: =IFERROR('Data Sheet'!K34,0) -> 1875.3
B22: Interest | C22: =IFERROR('Data Sheet'!F27,0) -> 39.44 | D22: =IFERROR('Data Sheet'!G27,0) -> 32.72 | E22: =IFERROR('Data Sheet'!H27,0) -> 49.4 | F22: =IFERROR('Data Sheet'!I27,0) -> 64.07 | G22: =IFERROR('Data Sheet'!J27,0) -> 80.96 | H22: =IFERROR('Data Sheet'!K27,0) -> 161.52
B23: Interest % Sales | C23: =IFERROR(C22/C6,0) -> 0.0089633919 | D23: =IFERROR(D22/D6,0) -> 0.0050743079 | E23: =IFERROR(E22/E6,0) -> 0.0046180827 | F23: =IFERROR(F22/F6,0) -> 0.005255081 | G23: =IFERROR(G22/G6,0) -> 0.0045763641 | H23: =IFERROR(H22/H6,0) -> 0.0041564484
B25: Depreciation | C25: =IFERROR('Data Sheet'!F26,0) -> 36.53 | D25: =IFERROR('Data Sheet'!G26,0) -> 43.72 | E25: =IFERROR('Data Sheet'!H26,0) -> 83.95 | F25: =IFERROR('Data Sheet'!I26,0) -> 114.63 | G25: =IFERROR('Data Sheet'!J26,0) -> 161.88 | H25: =IFERROR('Data Sheet'!K26,0) -> 281.02
B26: Depreciation%Sales | C26: =IFERROR(C25/C6,0) -> 0.0083020463 | D26: =IFERROR(D25/D6,0) -> 0.0067802183 | E26: =IFERROR(E25/E6,0) -> 0.0078479361 | F26: =IFERROR(F25/F6,0) -> 0.0094020592 | G26: =IFERROR(G25/G6,0) -> 0.0091504672 | H26: =IFERROR(H25/H6,0) -> 0.007231582
B28: Earnings Before Tax | C28: =IFERROR(C18-SUM(C25,C22),0) -> 151.86 | D28: =IFERROR(D18-SUM(D25,D22),0) -> 215.76 | E28: =IFERROR(E18-SUM(E25,E22),0) -> 250.95 | F28: =IFERROR(F18-SUM(F25,F22),0) -> 340.75 | G28: =IFERROR(G18-SUM(G25,G22),0) -> 462.21 | H28: =IFERROR(H18-SUM(H25,H22),0) -> 1072.31
B29: EBT % Sales | C29: =IFERROR(C28/C6,0) -> 0.034512695 | D29: =IFERROR(D28/D6,0) -> 0.033460656 | E29: =IFERROR(E28/E6,0) -> 0.023459673 | F29: =IFERROR(F28/F6,0) -> 0.027948632 | G29: =IFERROR(G28/G6,0) -> 0.026126992 | H29: =IFERROR(H28/H6,0) -> 0.027594113
B31: Tax | C31: =IFERROR('Data Sheet'!F29,0) -> 36.27 | D31: =IFERROR('Data Sheet'!G29,0) -> 57.21 | E31: =IFERROR('Data Sheet'!H29,0) -> 64.38 | F31: =IFERROR('Data Sheet'!I29,0) -> 89.7 | G31: =IFERROR('Data Sheet'!J29,0) -> 118.91 | H31: =IFERROR('Data Sheet'!K29,0) -> 337.22
B32: Effective Tax Rate | C32: =IFERROR(C31/C28,0) -> 0.2388384 | D32: =IFERROR(D31/D28,0) -> 0.26515573 | E32: =IFERROR(E31/E28,0) -> 0.25654513 | F32: =IFERROR(F31/F28,0) -> 0.26324285 | G32: =IFERROR(G31/G28,0) -> 0.25726401 | H32: =IFERROR(H31/H28,0) -> 0.31447995
B34: Net Profit | C34: =IFERROR(C28-C31,0) -> 115.59 | D34: =IFERROR(D28-D31,0) -> 158.55 | E34: =IFERROR(E28-E31,0) -> 186.57 | F34: =IFERROR(F28-F31,0) -> 251.05 | G34: =IFERROR(G28-G31,0) -> 343.3 | H34: =IFERROR(H28-H31,0) -> 735.09
B35: Net Margins | C35: =IFERROR(C34/C6,0) -> 0.026269738 | D35: =IFERROR(D34/D6,0) -> 0.024588372 | E35: =IFERROR(E34/E6,0) -> 0.017441208 | F35: =IFERROR(F34/F6,0) -> 0.020591355 | G35: =IFERROR(G34/G6,0) -> 0.019405457 | H35: =IFERROR(H34/H6,0) -> 0.018916318
B37: No of Equity Shares | C37: =IFERROR('Data Sheet'!F93,0) -> 5.79 | D37: =IFERROR('Data Sheet'!G93,0) -> 5.86 | E37: =IFERROR('Data Sheet'!H93,0) -> 5.93 | F37: =IFERROR('Data Sheet'!I93,0) -> 5.96 | G37: =IFERROR('Data Sheet'!J93,0) -> 5.98 | H37: =IFERROR('Data Sheet'!K93,0) -> 6.02
B39: Earnings per Share | C39: =IFERROR(C34/C37,0) -> 19.963731 | D39: =IFERROR(D34/D37,0) -> 27.056314 | E39: =IFERROR(E34/E37,0) -> 31.462057 | F39: =IFERROR(F34/F37,0) -> 42.122483 | G39: =IFERROR(G34/G37,0) -> 57.408027 | H39: =IFERROR(H34/H37,0) -> 122.10797
B40: EPS Growth % | C40: =IFERROR(C39/#REF!-1,0) -> 0 | D40: =IFERROR(D39/C39-1,0) -> 0.35527345 | E40: =IFERROR(E39/D39-1,0) -> 0.16283605 | F40: =IFERROR(F39/E39-1,0) -> 0.33883435 | G40: =IFERROR(G39/F39-1,0) -> 0.36288325 | H40: =IFERROR(H39/G39-1,0) -> 1.1270192
B42: Dividend per Share | C42: =IFERROR('Data Sheet'!F31/HistoricalFS!C37,0) -> 0.79965458 | D42: =IFERROR('Data Sheet'!G31/HistoricalFS!D37,0) -> 1 | E42: =IFERROR('Data Sheet'!H31/HistoricalFS!E37,0) -> 2.0016863 | F42: =IFERROR('Data Sheet'!I31/HistoricalFS!F37,0) -> 2.9966443 | G42: =IFERROR('Data Sheet'!J31/HistoricalFS!G37,0) -> 5 | H42: =IFERROR('Data Sheet'!K31/HistoricalFS!H37,0) -> 8.0066445
B43: Dividend payout ratio | C43: =IFERROR(C42/C39,0) -> 0.040055368 | D43: =IFERROR(D42/D39,0) -> 0.03695995 | E43: =IFERROR(E42/E39,0) -> 0.063622233 | F43: =IFERROR(F42/F39,0) -> 0.071141207 | G43: =IFERROR(G42/G39,0) -> 0.087095835 | H43: =IFERROR(H42/H39,0) -> 0.065570202
B45: Retained Earnings | C45: =IFERROR(IF(C39>C42,1-C43,0),0) -> 0.95994463 | D45: =IFERROR(IF(D39>D42,1-D43,0),0) -> 0.96304005 | E45: =IFERROR(IF(E39>E42,1-E43,0),0) -> 0.93637777 | F45: =IFERROR(IF(F39>F42,1-F43,0),0) -> 0.92885879 | G45: =IFERROR(IF(G39>G42,1-G43,0),0) -> 0.91290417 | H45: =IFERROR(IF(H39>H42,1-H43,0),0) -> 0.9344298
B47: Note: EBITDA (Operating) excludes Other Income to reflect core operating performance, while EBITDA (Reported, as per Screener) includes Other Income, leading to the variance
A50: # | B50: Balance Sheet
B51: Equity Share Capital | C51: =IFERROR('Data Sheet'!F57,0) -> 11.57 | D51: =IFERROR('Data Sheet'!G57,0) -> 11.71 | E51: =IFERROR('Data Sheet'!H57,0) -> 11.87 | F51: =IFERROR('Data Sheet'!I57,0) -> 11.91 | G51: =IFERROR('Data Sheet'!J57,0) -> 11.96 | H51: =IFERROR('Data Sheet'!K57,0) -> 12.05
B52: Reserves | C52: =IFERROR('Data Sheet'!F58,0) -> 529.76 | D52: =IFERROR('Data Sheet'!G58,0) -> 725.59 | E52: =IFERROR('Data Sheet'!H58,0) -> 984.91 | F52: =IFERROR('Data Sheet'!I58,0) -> 1273 | G52: =IFERROR('Data Sheet'!J58,0) -> 1682.89 | H52: =IFERROR('Data Sheet'!K58,0) -> 2998.15
B53: Borrowings | C53: =IFERROR('Data Sheet'!F59,0) -> 86.67 | D53: =IFERROR('Data Sheet'!G59,0) -> 294.53 | E53: =IFERROR('Data Sheet'!H59,0) -> 666.9 | F53: =IFERROR('Data Sheet'!I59,0) -> 453.09 | G53: =IFERROR('Data Sheet'!J59,0) -> 488.98 | H53: =IFERROR('Data Sheet'!K59,0) -> 670.96
B54: Other Liabilities | C54: =IFERROR('Data Sheet'!F60,0) -> 1068.96 | D54: =IFERROR('Data Sheet'!G60,0) -> 1813.83 | E54: =IFERROR('Data Sheet'!H60,0) -> 2613.49 | F54: =IFERROR('Data Sheet'!I60,0) -> 2941.43 | G54: =IFERROR('Data Sheet'!J60,0) -> 4805.7 | H54: =IFERROR('Data Sheet'!K60,0) -> 13076.59
B55: Total Liabilities | C55: =IFERROR('Data Sheet'!F61,0) -> 1696.96 | D55: =IFERROR('Data Sheet'!G61,0) -> 2845.66 | E55: =IFERROR('Data Sheet'!H61,0) -> 4277.17 | F55: =IFERROR('Data Sheet'!I61,0) -> 4679.43 | G55: =IFERROR('Data Sheet'!J61,0) -> 6989.53 | H55: =IFERROR('Data Sheet'!K61,0) -> 16757.75
B57: Fixed Assets Net Block | C57: =IFERROR('Data Sheet'!F62,0) -> 414.08 | D57: =IFERROR('Data Sheet'!G62,0) -> 550.23 | E57: =IFERROR('Data Sheet'!H62,0) -> 1003.29 | F57: =IFERROR('Data Sheet'!I62,0) -> 1243.64 | G57: =IFERROR('Data Sheet'!J62,0) -> 1996.25 | H57: =IFERROR('Data Sheet'!K62,0) -> 2773.76
B58: Capital Work in Progress | C58: =IFERROR('Data Sheet'!F63,0) -> 9.55 | D58: =IFERROR('Data Sheet'!G63,0) -> 72.39 | E58: =IFERROR('Data Sheet'!H63,0) -> 22.39 | F58: =IFERROR('Data Sheet'!I63,0) -> 119.7 | G58: =IFERROR('Data Sheet'!J63,0) -> 68.34 | H58: =IFERROR('Data Sheet'!K63,0) -> 256.95
B59: Investments | C59: =IFERROR('Data Sheet'!F64,0) -> 0 | D59: =IFERROR('Data Sheet'!G64,0) -> 95.25 | E59: =IFERROR('Data Sheet'!H64,0) -> 140.96 | F59: =IFERROR('Data Sheet'!I64,0) -> 44.15 | G59: =IFERROR('Data Sheet'!J64,0) -> 20.04 | H59: =IFERROR('Data Sheet'!K64,0) -> 535.6
...

Sheet Ratio Analysis
B2: ="Ratio Analysis of - "&'Data Sheet'!B1 -> Ratio Analysis of - DIXON TECHNOLOGIES (INDIA) LTD
B3: Years | C3: ='Data Sheet'!F16 -> 43921 | D3: ='Data Sheet'!G16 -> 44286 | E3: ='Data Sheet'!H16 -> 44651 | F3: ='Data Sheet'!I16 -> 45016 | G3: ='Data Sheet'!J16 -> 45382 | H3: ='Data Sheet'!K16 -> 45747 | I3: Trend | J3: Mean | K3: Median
B5: SalesGrowth | C5: =IFERROR(HistoricalFS!C7,0) -> 0 | D5: =IFERROR(HistoricalFS!D7,0) -> 0.46545321 | E5: =IFERROR(HistoricalFS!E7,0) -> 0.65893269 | F5: =IFERROR(HistoricalFS!F7,0) -> 0.13975122 | G5: =IFERROR(HistoricalFS!G7,0) -> 0.45102407 | H5: =IFERROR(HistoricalFS!H7,0) -> 1.1966152 | J5: =IFERROR(AVERAGE(C5:H5),0) -> 0.48529607 | K5: =IFERROR(MEDIAN(C5:H5),0) -> 0.45823864
B6: EBITDA Growth | C6: =IFERROR(HistoricalFS!C18/HistoricalFS!#REF!-1,0) -> 0 | D6: =IFERROR(HistoricalFS!D18/HistoricalFS!C18-1,0) -> 0.28253522 | E6: =IFERROR(HistoricalFS!E18/HistoricalFS!D18-1,0) -> 0.31519507 | F6: =IFERROR(HistoricalFS!F18/HistoricalFS!E18-1,0) -> 0.35167838 | G6: =IFERROR(HistoricalFS!G18/HistoricalFS!F18-1,0) -> 0.35730099 | H6: =IFERROR(HistoricalFS!H18/HistoricalFS!G18-1,0) -> 1.148571 | J6: =IFERROR(AVERAGE(C6:H6),0) -> 0.40921345 | K6: =IFERROR(MEDIAN(C6:H6),0) -> 0.33343672
B7: EBIT Growth | C7: =IFERROR(HistoricalFS!C28/HistoricalFS!#REF!-1,0) -> 0 | D7: =IFERROR(HistoricalFS!D28/HistoricalFS!C28-1,0) -> 0.4207823 | E7: =IFERROR(HistoricalFS!E28/HistoricalFS!D28-1,0) -> 0.16309789 | F7: =IFERROR(HistoricalFS!F28/HistoricalFS!E28-1,0) -> 0.35784021 | G7: =IFERROR(HistoricalFS!G28/HistoricalFS!F28-1,0) -> 0.35644901 | H7: =IFERROR(HistoricalFS!H28/HistoricalFS!G28-1,0) -> 1.3199628 | J7: =IFERROR(AVERAGE(C7:H7),0) -> 0.43635537 | K7: =IFERROR(MEDIAN(C7:H7),0) -> 0.35714461
B8: Net Profit Growth | C8: =IFERROR(HistoricalFS!C34/HistoricalFS!#REF!-1,0) -> 0 | D8: =IFERROR(HistoricalFS!D34/HistoricalFS!C34-1,0) -> 0.37165845 | E8: =IFERROR(HistoricalFS!E34/HistoricalFS!D34-1,0) -> 0.17672658 | F8: =IFERROR(HistoricalFS!F34/HistoricalFS!E34-1,0) -> 0.34560755 | G8: =IFERROR(HistoricalFS!G34/HistoricalFS!F34-1,0) -> 0.36745668 | H8: =IFERROR(HistoricalFS!H34/HistoricalFS!G34-1,0) -> 1.1412467 | J8: =IFERROR(AVERAGE(C8:H8),0) -> 0.40044933 | K8: =IFERROR(MEDIAN(C8:H8),0) -> 0.35653211
B9: Dividend Growth | C9: =IFERROR(HistoricalFS!C42/HistoricalFS!#REF!-1,0) -> 0 | D9: =IFERROR(HistoricalFS!D42/HistoricalFS!C42-1,0) -> 0.25053996 | E9: =IFERROR(HistoricalFS!E42/HistoricalFS!D42-1,0) -> 1.0016863 | F9: =IFERROR(HistoricalFS!F42/HistoricalFS!E42-1,0) -> 0.49705987 | G9: =IFERROR(HistoricalFS!G42/HistoricalFS!F42-1,0) -> 0.66853303 | H9: =IFERROR(HistoricalFS!H42/HistoricalFS!G42-1,0) -> 0.6013289 | J9: =IFERROR(AVERAGE(C9:H9),0) -> 0.50319135 | K9: =IFERROR(MEDIAN(C9:H9),0) -> 0.54919439
B11: Gross Margin | C11: =IFERROR(HistoricalFS!C13,0) -> 0.063727807 | D11: =IFERROR(HistoricalFS!D13,0) -> 0.056639326 | E11: =IFERROR(HistoricalFS!E13,0) -> 0.044097081 | F11: =IFERROR(HistoricalFS!F13,0) -> 0.051319676 | G11: =IFERROR(HistoricalFS!G13,0) -> 0.047266109 | H11: =IFERROR(HistoricalFS!H13,0) -> 0.044873534 | J11: =IFERROR(AVERAGE(C11:H11),0) -> 0.051320589 | K11: =IFERROR(MEDIAN(C11:H11),0) -> 0.049292892
B12: EBITDA Margin | C12: =IFERROR(HistoricalFS!C19,0) -> 0.051778133 | D12: =IFERROR(HistoricalFS!D19,0) -> 0.045315182 | E12: =IFERROR(HistoricalFS!E19,0) -> 0.035925692 | F12: =IFERROR(HistoricalFS!F19,0) -> 0.042605772 | G12: =IFERROR(HistoricalFS!G19,0) -> 0.039853823 | H12: =IFERROR(HistoricalFS!H19,0) -> 0.038982144 | J12: =IFERROR(AVERAGE(C12:H12),0) -> 0.042410124 | K12: =IFERROR(MEDIAN(C12:H12),0) -> 0.041229798
B13: EBIT Margin | C13: =IFERROR((HistoricalFS!C28+HistoricalFS!C22)/HistoricalFS!C6,0) -> 0.043476087 | D13: =IFERROR((HistoricalFS!D28+HistoricalFS!D22)/HistoricalFS!D6,0) -> 0.038534964 | E13: =IFERROR((HistoricalFS!E28+HistoricalFS!E22)/HistoricalFS!E6,0) -> 0.028077756 | F13: =IFERROR((HistoricalFS!F28+HistoricalFS!F22)/HistoricalFS!F6,0) -> 0.033203713 | G13: =IFERROR((HistoricalFS!G28+HistoricalFS!G22)/HistoricalFS!G6,0) -> 0.030703356 | H13: =IFERROR((HistoricalFS!H28+HistoricalFS!H22)/HistoricalFS!H6,0) -> 0.031750562 | J13: =IFERROR(AVERAGE(C13:H13),0) -> 0.034291073 | K13: =IFERROR(MEDIAN(C13:H13),0) -> 0.032477137
B14: EBT Margin | C14: =IFERROR(HistoricalFS!C29,0) -> 0.034512695 | D14: =IFERROR(HistoricalFS!D29,0) -> 0.033460656 | E14: =IFERROR(HistoricalFS!E29,0) -> 0.023459673 | F14: =IFERROR(HistoricalFS!F29,0) -> 0.027948632 | G14: =IFERROR(HistoricalFS!G29,0) -> 0.026126992 | H14: =IFERROR(HistoricalFS!H29,0) -> 0.027594113 | J14: =IFERROR(AVERAGE(C14:H14),0) -> 0.02885046 | K14: =IFERROR(MEDIAN(C14:H14),0) -> 0.027771373
B15: Net Profit Margin | C15: =IFERROR(HistoricalFS!C35,0) -> 0.026269738 | D15: =IFERROR(HistoricalFS!D35,0) -> 0.024588372 | E15: =IFERROR(HistoricalFS!E35,0) -> 0.017441208 | F15: =IFERROR(HistoricalFS!F35,0) -> 0.020591355 | G15: =IFERROR(HistoricalFS!G35,0) -> 0.019405457 | H15: =IFERROR(HistoricalFS!H35,0) -> 0.018916318 | J15: =IFERROR(AVERAGE(C15:H15),0) -> 0.021202075 | K15: =IFERROR(MEDIAN(C15:H15),0) -> 0.019998406
B17: SalesExpenses%Sales | C17: =IFERROR(HistoricalFS!C16,0) -> 0.011949674 | D17: =IFERROR(HistoricalFS!D16,0) -> 0.011324143 | E17: =IFERROR(HistoricalFS!E16,0) -> 0.0081713888 | F17: =IFERROR(HistoricalFS!F16,0) -> 0.0087139036 | G17: =IFERROR(HistoricalFS!G16,0) -> 0.0074122854 | H17: =IFERROR(HistoricalFS!H16,0) -> 0.0058913899 | J17: =IFERROR(AVERAGE(C17:H17),0) -> 0.0089104642 | K17: =IFERROR(MEDIAN(C17:H17),0) -> 0.0084426462
B18: Depreciation%Sales | C18: =IFERROR(HistoricalFS!C26,0) -> 0.0083020463 | D18: =IFERROR(HistoricalFS!D26,0) -> 0.0067802183 | E18: =IFERROR(HistoricalFS!E26,0) -> 0.0078479361 | F18: =IFERROR(HistoricalFS!F26,0) -> 0.0094020592 | G18: =IFERROR(HistoricalFS!G26,0) -> 0.0091504672 | H18: =IFERROR(HistoricalFS!H26,0) -> 0.007231582 | J18: =IFERROR(AVERAGE(C18:H18),0) -> 0.0081190515 | K18: =IFERROR(MEDIAN(C18:H18),0) -> 0.0080749912
B19: OperatingIncome%Sales | C19: =C13 -> 0.043476087 | D19: =D13 -> 0.038534964 | E19: =E13 -> 0.028077756 | F19: =F13 -> 0.033203713 | G19: =G13 -> 0.030703356 | H19: =H13 -> 0.031750562 | J19: =IFERROR(AVERAGE(C19:H19),0) -> 0.034291073 | K19: =IFERROR(MEDIAN(C19:H19),0) -> 0.032477137
B21: Return on Capital Employed | C21: =IFERROR(((HistoricalFS!C18-HistoricalFS!C25)/SUM(HistoricalFS!C51:C53)),0) -> 0.30461783 | D21: =IFERROR(((HistoricalFS!D18-HistoricalFS!D25)/SUM(HistoricalFS!D51:D53)),0) -> 0.24081486 | E21: =IFERROR(((HistoricalFS!E18-HistoricalFS!E25)/SUM(HistoricalFS!E51:E53)),0) -> 0.18053352 | F21: =IFERROR(((HistoricalFS!F18-HistoricalFS!F25)/SUM(HistoricalFS!F51:F53)),0) -> 0.2329229 | G21: =IFERROR(((HistoricalFS!G18-HistoricalFS!G25)/SUM(HistoricalFS!G51:G53)),0) -> 0.24872357 | H21: =IFERROR(((HistoricalFS!H18-HistoricalFS!H25)/SUM(HistoricalFS!H51:H53)),0) -> 0.33517424 | J21: =IFERROR(AVERAGE(C21:H21),0) -> 0.25713115 | K21: =IFERROR(MEDIAN(C21:H21),0) -> 0.24476922
B22: Retained Earnings% | C22: =IFERROR(HistoricalFS!C45,0) -> 0.95994463 | D22: =IFERROR(HistoricalFS!D45,0) -> 0.96304005 | E22: =IFERROR(HistoricalFS!E45,0) -> 0.93637777 | F22: =IFERROR(HistoricalFS!F45,0) -> 0.92885879 | G22: =IFERROR(HistoricalFS!G45,0) -> 0.91290417 | H22: =IFERROR(HistoricalFS!H45,0) -> 0.9344298 | J22: =IFERROR(AVERAGE(C22:H22),0) -> 0.9392592 | K22: =IFERROR(MEDIAN(C22:H22),0) -> 0.93540378
B23: Return on Equity% | C23: =IFERROR(HistoricalFS!C34/SUM(HistoricalFS!C51:C52),0) -> 0.21352964 | D23: =IFERROR(HistoricalFS!D34/SUM(HistoricalFS!D51:D52),0) -> 0.21504137 | E23: =IFERROR(HistoricalFS!E34/SUM(HistoricalFS!E51:E52),0) -> 0.1871727 | F23: =IFERROR(HistoricalFS!F34/SUM(HistoricalFS!F51:F52),0) -> 0.19538333 | G23: =IFERROR(HistoricalFS!G34/SUM(HistoricalFS!G51:G52),0) -> 0.2025548 | H23: =IFERROR(HistoricalFS!H34/SUM(HistoricalFS!H51:H52),0) -> 0.24419972 | J23: =IFERROR(AVERAGE(C23:H23),0) -> 0.20964693 | K23: =IFERROR(MEDIAN(C23:H23),0) -> 0.20804222
B24: Self Sustained Growth Rate | C24: =IFERROR(C23*C22,0) -> 0.20497663 | D24: =IFERROR(D23*D22,0) -> 0.20709345 | E24: =IFERROR(E23*E22,0) -> 0.17526435 | F24: =IFERROR(F23*F22,0) -> 0.18148353 | G24: =IFERROR(G23*G22,0) -> 0.18491312 | H24: =IFERROR(H23*H22,0) -> 0.2281875 | J24: =IFERROR(AVERAGE(C24:H24),0) -> 0.19698643 | K24: =IFERROR(MEDIAN(C24:H24),0) -> 0.19494488
B25: Interest Coverage Ratio | C25: =IFERROR((HistoricalFS!C28+HistoricalFS!C22)/HistoricalFS!C22,0) -> 4.8504057 | D25: =IFERROR((HistoricalFS!D28+HistoricalFS!D22)/HistoricalFS!D22,0) -> 7.594132 | E25: =IFERROR((HistoricalFS!E28+HistoricalFS!E22)/HistoricalFS!E22,0) -> 6.0799595 | F25: =IFERROR((HistoricalFS!F28+HistoricalFS!F22)/HistoricalFS!F22,0) -> 6.3184017 | G25: =IFERROR((HistoricalFS!G28+HistoricalFS!G22)/HistoricalFS!G22,0) -> 6.7091156 | H25: =IFERROR((HistoricalFS!H28+HistoricalFS!H22)/HistoricalFS!H22,0) -> 7.6388683 | J25: =IFERROR(AVERAGE(C25:H25),0) -> 6.5318138 | K25: =IFERROR(MEDIAN(C25:H25),0) -> 6.5137587
B27: Debtor Turnover Ratio | C27: =IFERROR(HistoricalFS!C6/HistoricalFS!C63,0) -> 8.541932 | D27: =IFERROR(HistoricalFS!D6/HistoricalFS!D63,0) -> 5.9208584 | E27: =IFERROR(HistoricalFS!E6/HistoricalFS!E63,0) -> 7.8866664 | F27: =IFERROR(HistoricalFS!F6/HistoricalFS!F63,0) -> 7.1071789 | G27: =IFERROR(HistoricalFS!G6/HistoricalFS!G63,0) -> 7.6323623 | H27: =IFERROR(HistoricalFS!H6/HistoricalFS!H63,0) -> 5.5789791 | J27: =IFERROR(AVERAGE(C27:H27),0) -> 7.1113295 | K27: =IFERROR(MEDIAN(C27:H27),0) -> 7.3697706
B28: Creditor Turnover Ratio | C28: =IFERROR(HistoricalFS!C6/HistoricalFS!C54, 0) -> 4.1162625 | D28: =IFERROR(HistoricalFS!D6/HistoricalFS!D54, 0) -> 3.5550024 | E28: =IFERROR(HistoricalFS!E6/HistoricalFS!E54, 0) -> 4.093025 | F28: =IFERROR(HistoricalFS!F6/HistoricalFS!F54, 0) -> 4.1449261 | G28: =IFERROR(HistoricalFS!G6/HistoricalFS!G54, 0) -> 3.6812327 | H28: =IFERROR(HistoricalFS!H6/HistoricalFS!H54, 0) -> 2.9717304 | J28: =IFERROR(AVERAGE(C28:H28),0) -> 3.7603632 | K28: =IFERROR(MEDIAN(C28:H28),0) -> 3.8871289
B29: Inventory Turnover | C29: =IFERROR(HistoricalFS!C6/HistoricalFS!C64,0) -> 8.838422 | D29: =IFERROR(HistoricalFS!D6/HistoricalFS!D64,0) -> 8.6756408 | E29: =IFERROR(HistoricalFS!E6/HistoricalFS!E64,0) -> 9.2560116 | F29: =IFERROR(HistoricalFS!F6/HistoricalFS!F64,0) -> 12.728251 | G29: =IFERROR(HistoricalFS!G6/HistoricalFS!G64,0) -> 10.437048 | H29: =IFERROR(HistoricalFS!H6/HistoricalFS!H64,0) -> 9.7335187 | J29: =IFERROR(AVERAGE(C29:H29),0) -> 9.9448153 | K29: =IFERROR(MEDIAN(C29:H29),0) -> 9.4947651
B30: Fixed Asset Turnover | C30: =IFERROR(HistoricalFS!C6/HistoricalFS!C57,0) -> 10.626256 | D30: =IFERROR(HistoricalFS!D6/HistoricalFS!D57,0) -> 11.719045 | E30: =IFERROR(HistoricalFS!E6/HistoricalFS!E57,0) -> 10.662002 | F30: =IFERROR(HistoricalFS!F6/HistoricalFS!F57,0) -> 9.8034881 | G30: =IFERROR(HistoricalFS!G6/HistoricalFS!G57,0) -> 8.8620664 | H30: =IFERROR(HistoricalFS!H6/HistoricalFS!H57,0) -> 14.0099 | J30: =IFERROR(AVERAGE(C30:H30),0) -> 10.947126 | K30: =IFERROR(MEDIAN(C30:H30),0) -> 10.644129
B31: Capital Turnover Ratio | C31: =IFERROR(HistoricalFS!C6/SUM(HistoricalFS!C51:C52),0) -> 8.1283505 | D31: =IFERROR(HistoricalFS!D6/SUM(HistoricalFS!D51:D52),0) -> 8.7456531 | E31: =IFERROR(HistoricalFS!E6/SUM(HistoricalFS!E51:E52),0) -> 10.731636 | F31: =IFERROR(HistoricalFS!F6/SUM(HistoricalFS!F51:F52),0) -> 9.4886101 | G31: =IFERROR(HistoricalFS!G6/SUM(HistoricalFS!G51:G52),0) -> 10.438033 | H31: =IFERROR(HistoricalFS!H6/SUM(HistoricalFS!H51:H52),0) -> 12.909474 | J31: =IFERROR(AVERAGE(C31:H31),0) -> 10.073626 | K31: =IFERROR(MEDIAN(C31:H31),0) -> 9.9633215
B33: (in Days)
B34: Debtor Days | C34: =IFERROR(365/C27,0) -> 42.73038 | D34: =IFERROR(365/D27,0) -> 61.646467 | E34: =IFERROR(365/E27,0) -> 46.280644 | F34: =IFERROR(365/F27,0) -> 51.356524 | G34: =IFERROR(365/G27,0) -> 47.822677 | H34: =IFERROR(365/H27,0) -> 65.424156 | J34: =IFERROR(AVERAGE(C34:H34),0) -> 52.543475 | K34: =IFERROR(MEDIAN(C34:H34),0) -> 49.5896
B35: Payable Days | C35: =IFERROR(365/C28,0) -> 88.672673 | D35: =IFERROR(365/D28,0) -> 102.67222 | E35: =IFERROR(365/E28,0) -> 89.176098 | F35: =IFERROR(365/F28,0) -> 88.059471 | G35: =IFERROR(365/G28,0) -> 99.151569 | H35: =IFERROR(365/H28,0) -> 122.82406 | J35: =IFERROR(AVERAGE(C35:H35),0) -> 98.426016 | K35: =IFERROR(MEDIAN(C35:H35),0) -> 94.163834
B36: Inventory Days | C36: =IFERROR(365/C29,0) -> 41.296965 | D36: =IFERROR(365/D29,0) -> 42.07182 | E36: =IFERROR(365/E29,0) -> 39.433831 | F36: =IFERROR(365/F29,0) -> 28.676367 | G36: =IFERROR(365/G29,0) -> 34.971576 | H36: =IFERROR(365/H29,0) -> 37.499286 | J36: =IFERROR(AVERAGE(C36:H36),0) -> 37.324974 | K36: =IFERROR(MEDIAN(C36:H36),0) -> 38.466559
B37: Cash Conversion Cycle | C37: =IFERROR(SUM(C34,C36)-C35,0) -> -4.6453279 | D37: =IFERROR(SUM(D34,D36)-D35,0) -> 1.0460642 | E37: =IFERROR(SUM(E34,E36)-E35,0) -> -3.4616222 | F37: =IFERROR(SUM(F34,F36)-F35,0) -> -8.0265805 | G37: =IFERROR(SUM(G34,G36)-G35,0) -> -16.357316 | H37: =IFERROR(SUM(H34,H36)-H35,0) -> -19.90062 | J37: =IFERROR(AVERAGE(C37:H37),0) -> -8.5575672 | K37: =IFERROR(MEDIAN(C37:H37),0) -> -6.3359542
B39: CFO/Sales | C39: =IFERROR(HistoricalFS!C74/HistoricalFS!C6, 0) -> 0.053939438 | D39: =IFERROR(HistoricalFS!D74/HistoricalFS!D6, 0) -> 0.026381128 | E39: =IFERROR(HistoricalFS!E74/HistoricalFS!E6, 0) -> 0.025496678 | F39: =IFERROR(HistoricalFS!F74/HistoricalFS!F6, 0) -> 0.05952669 | G39: =IFERROR(HistoricalFS!G74/HistoricalFS!G6, 0) -> 0.033028845 | H39: =IFERROR(HistoricalFS!H74/HistoricalFS!H6, 0) -> 0.029586903 | J39: =IFERROR(AVERAGE(C39:H39),0) -> 0.03799328 | K39: =IFERROR(MEDIAN(C39:H39),0) -> 0.031307874
B40: CFO/Total Assets | C40: =IFERROR(HistoricalFS!C74/HistoricalFS!C68, 0) -> 0.13986187 | D40: =IFERROR(HistoricalFS!D74/HistoricalFS!D68, 0) -> 0.059778751 | E40: =IFERROR(HistoricalFS!E74/HistoricalFS!E68, 0) -> 0.063766462 | F40: =IFERROR(HistoricalFS!F74/HistoricalFS!F68, 0) -> 0.15509368 | G40: =IFERROR(HistoricalFS!G74/HistoricalFS!G68, 0) -> 0.083597896 | H40: =IFERROR(HistoricalFS!H74/HistoricalFS!H68, 0) -> 0.068610046 | J40: =IFERROR(AVERAGE(C40:H40),0) -> 0.095118117 | K40: =IFERROR(MEDIAN(C40:H40),0) -> 0.076103971
B41: CFO/Total Debt | C41: =IFERROR(HistoricalFS!C74/HistoricalFS!C53,0) -> 2.7384331 | D41: =IFERROR(HistoricalFS!D74/HistoricalFS!D53,0) -> 0.57756425 | E41: =IFERROR(HistoricalFS!E74/HistoricalFS!E53,0) -> 0.40896686 | F41: =IFERROR(HistoricalFS!F74/HistoricalFS!F53,0) -> 1.6017789 | G41: =IFERROR(HistoricalFS!G74/HistoricalFS!G53,0) -> 1.1949568 | H41: =IFERROR(HistoricalFS!H74/HistoricalFS!H53,0) -> 1.7135895 | J41: =IFERROR(AVERAGE(C41:H41),0) -> 1.3725482 | K41: =IFERROR(MEDIAN(C41:H41),0) -> 1.3983679

Sheet Common Size Statement
A2: # | B2: ="Common Size Income Statement - "&'Data Sheet'!$B$1 -> Common Size Income Statement - DIXON TECHNOLOGIES (INDIA) LTD
B4: Particulars | C4: ='Data Sheet'!F$56 -> 43921 | D4: ='Data Sheet'!G$56 -> 44286 | E4: ='Data Sheet'!H$56 -> 44651 | F4: ='Data Sheet'!I$56 -> 45016 | G4: ='Data Sheet'!J$56 -> 45382 | H4: ='Data Sheet'!K$56 -> 45747
B6: ='Data Sheet'!A17 -> Sales | C6: ='Data Sheet'!F17/'Data Sheet'!F$17 -> 1 | D6: ='Data Sheet'!G17/'Data Sheet'!G$17 -> 1 | E6: ='Data Sheet'!H17/'Data Sheet'!H$17 -> 1 | F6: ='Data Sheet'!I17/'Data Sheet'!I$17 -> 1 | G6: ='Data Sheet'!J17/'Data Sheet'!J$17 -> 1 | H6: ='Data Sheet'!K17/'Data Sheet'!K$17 -> 1
B7: ='Data Sheet'!A18 -> Raw Material Cost | C7: ='Data Sheet'!F18/'Data Sheet'!F$17 -> 0.8893712 | D7: ='Data Sheet'!G18/'Data Sheet'!G$17 -> 0.8922547 | E7: ='Data Sheet'!H18/'Data Sheet'!H$17 -> 0.92451959 | F7: ='Data Sheet'!I18/'Data Sheet'!I$17 -> 0.90347449 | G7: ='Data Sheet'!J18/'Data Sheet'!J$17 -> 0.91247025 | H7: ='Data Sheet'!K18/'Data Sheet'!K$17 -> 0.92896853
B8: ='Data Sheet'!A19 -> Change in Inventory | C8: ='Data Sheet'!F19/'Data Sheet'!F$17 -> 0.012076943 | D8: ='Data Sheet'!G19/'Data Sheet'!G$17 -> -0.0025293998 | E8: ='Data Sheet'!H19/'Data Sheet'!H$17 -> 0.010322443 | F8: ='Data Sheet'!I19/'Data Sheet'!I$17 -> -0.00045685658 | G8: ='Data Sheet'!J19/'Data Sheet'!J$17 -> 0.0058487697 | H8: ='Data Sheet'!K19/'Data Sheet'!K$17 -> 0.0068705433
B9: ='Data Sheet'!A20 -> Power and Fuel | C9: ='Data Sheet'!F20/'Data Sheet'!F$17 -> 0.0050453169 | D9: ='Data Sheet'!G20/'Data Sheet'!G$17 -> 0.004092634 | E9: ='Data Sheet'!H20/'Data Sheet'!H$17 -> 0.0037776664 | F9: ='Data Sheet'!I20/'Data Sheet'!I$17 -> 0.0038820506 | G9: ='Data Sheet'!J20/'Data Sheet'!J$17 -> 0.0037188611 | H9: ='Data Sheet'!K20/'Data Sheet'!K$17 -> 0.0026286602
B10: ='Data Sheet'!A21 -> Other Mfr. Exp | C10: ='Data Sheet'!F21/'Data Sheet'!F$17 -> 0.02712426 | D10: ='Data Sheet'!G21/'Data Sheet'!G$17 -> 0.023206584 | E10: ='Data Sheet'!H21/'Data Sheet'!H$17 -> 0.019411839 | F10: ='Data Sheet'!I21/'Data Sheet'!I$17 -> 0.020202575 | G10: ='Data Sheet'!J21/'Data Sheet'!J$17 -> 0.023578224 | H10: ='Data Sheet'!K21/'Data Sheet'!K$17 -> 0.015787144
B11: ='Data Sheet'!A22 -> Employee Cost | C11: ='Data Sheet'!F22/'Data Sheet'!F$17 -> 0.02680836 | D11: ='Data Sheet'!G22/'Data Sheet'!G$17 -> 0.021277355 | E11: ='Data Sheet'!H22/'Data Sheet'!H$17 -> 0.018516268 | F11: ='Data Sheet'!I22/'Data Sheet'!I$17 -> 0.020664353 | G11: ='Data Sheet'!J22/'Data Sheet'!J$17 -> 0.018815323 | H11: ='Data Sheet'!K22/'Data Sheet'!K$17 -> 0.014612675
B12: ='Data Sheet'!A23 -> Selling and admin | C12: ='Data Sheet'!F23/'Data Sheet'!F$17 -> 0.0052225848 | D12: ='Data Sheet'!G23/'Data Sheet'!G$17 -> 0.005721003 | E12: ='Data Sheet'!H23/'Data Sheet'!H$17 -> 0.0042600411 | F12: ='Data Sheet'!I23/'Data Sheet'!I$17 -> 0.0041272932 | G12: ='Data Sheet'!J23/'Data Sheet'!J$17 -> 0.0030948115 | H12: ='Data Sheet'!K23/'Data Sheet'!K$17 -> 0.0018116268
B13: ='Data Sheet'!A24 -> Other Expenses | C13: ='Data Sheet'!F24/'Data Sheet'!F$17 -> 0.0067270893 | D13: ='Data Sheet'!G24/'Data Sheet'!G$17 -> 0.0056031401 | E13: ='Data Sheet'!H24/'Data Sheet'!H$17 -> 0.0039113478 | F13: ='Data Sheet'!I24/'Data Sheet'!I$17 -> 0.0045866104 | G13: ='Data Sheet'!J24/'Data Sheet'!J$17 -> 0.004317474 | H13: ='Data Sheet'!K24/'Data Sheet'!K$17 -> 0.004079763
B14: ='Data Sheet'!A25 -> Other Income | C14: ='Data Sheet'!F25/'Data Sheet'!F$17 -> 0.001113606 | D14: ='Data Sheet'!G25/'Data Sheet'!G$17 -> 0.00019385345 | E14: ='Data Sheet'!H25/'Data Sheet'!H$17 -> 0.00035149779 | F14: ='Data Sheet'!I25/'Data Sheet'!I$17 -> 0.00033054435 | G14: ='Data Sheet'!J25/'Data Sheet'!J$17 -> 0.0017873596 | H14: ='Data Sheet'!K25/'Data Sheet'!K$17 -> 0.012802077
B15: ='Data Sheet'!A26 -> Depreciation | C15: ='Data Sheet'!F26/'Data Sheet'!F$17 -> 0.0083020463 | D15: ='Data Sheet'!G26/'Data Sheet'!G$17 -> 0.0067802183 | E15: ='Data Sheet'!H26/'Data Sheet'!H$17 -> 0.0078479361 | F15: ='Data Sheet'!I26/'Data Sheet'!I$17 -> 0.0094020592 | G15: ='Data Sheet'!J26/'Data Sheet'!J$17 -> 0.0091504672 | H15: ='Data Sheet'!K26/'Data Sheet'!K$17 -> 0.007231582
B16: ='Data Sheet'!A27 -> Interest | C16: ='Data Sheet'!F27/'Data Sheet'!F$17 -> 0.0089633919 | D16: ='Data Sheet'!G27/'Data Sheet'!G$17 -> 0.0050743079 | E16: ='Data Sheet'!H27/'Data Sheet'!H$17 -> 0.0046180827 | F16: ='Data Sheet'!I27/'Data Sheet'!I$17 -> 0.005255081 | G16: ='Data Sheet'!J27/'Data Sheet'!J$17 -> 0.0045763641 | H16: ='Data Sheet'!K27/'Data Sheet'!K$17 -> 0.0041564484
B17: ='Data Sheet'!A28 -> Profit before tax | C17: ='Data Sheet'!F28/'Data Sheet'!F$17 -> 0.035626301 | D17: ='Data Sheet'!G28/'Data Sheet'!G$17 -> 0.03365451 | E17: ='Data Sheet'!H28/'Data Sheet'!H$17 -> 0.023811171 | F17: ='Data Sheet'!I28/'Data Sheet'!I$17 -> 0.028279176 | G17: ='Data Sheet'!J28/'Data Sheet'!J$17 -> 0.027914351 | H17: ='Data Sheet'!K28/'Data Sheet'!K$17 -> 0.04039619
... B20: ='Data Sheet'!A31 -> Dividend Amount | C20: ='Data Sheet'!F31/'Data Sheet'!F$17 -> 0.001052244 | D20: ='Data Sheet'!G31/'Data Sheet'!G$17 -> 0.00090878497 | E20: ='Data Sheet'!H31/'Data Sheet'!H$17 -> 0.0011096486 | F20: ='Data Sheet'!I31/'Data Sheet'!I$17 -> 0.0014648938 | G20: ='Data Sheet'!J31/'Data Sheet'!J$17 -> 0.0016901345 | H20: ='Data Sheet'!K31/'Data Sheet'!K$17 -> 0.0012403468
B21: ='Data Sheet'!A34 -> EBITDA | C21: ='Data Sheet'!F34/'Data Sheet'!F$17 -> 0.052894012 | D21: ='Data Sheet'!G34/'Data Sheet'!G$17 -> 0.045509036 | E21: ='Data Sheet'!H34/'Data Sheet'!H$17 -> 0.036262232 | F21: ='Data Sheet'!I34/'Data Sheet'!I$17 -> 0.042972406 | G21: ='Data Sheet'!J34/'Data Sheet'!J$17 -> 0.04123589 | H21: ='Data Sheet'!K34/'Data Sheet'!K$17 -> 0.048257725
B25: ="Common Size Balancesheet - "&'Data Sheet'!$B$1 -> Common Size Balancesheet - DIXON TECHNOLOGIES (INDIA) LTD
A26: #
B27: Particulars | C27: ='Data Sheet'!F$56 -> 43921 | D27: ='Data Sheet'!G$56 -> 44286 | E27: ='Data Sheet'!H$56 -> 44651 | F27: ='Data Sheet'!I$56 -> 45016 | G27: ='Data Sheet'!J$56 -> 45382 | H27: ='Data Sheet'!K$56 -> 45747
B29: Total Liabilities | C29: ='Data Sheet'!F61/'Data Sheet'!F$61 -> 1 | D29: ='Data Sheet'!G61/'Data Sheet'!G$61 -> 1 | E29: ='Data Sheet'!H61/'Data Sheet'!H$61 -> 1 | F29: ='Data Sheet'!I61/'Data Sheet'!I$61 -> 1 | G29: ='Data Sheet'!J61/'Data Sheet'!J$61 -> 1 | H29: ='Data Sheet'!K61/'Data Sheet'!K$61 -> 1
B30: ='Data Sheet'!A57 -> Equity Share Capital | C30: ='Data Sheet'!F57/'Data Sheet'!F$61 -> 0.0068180747 | D30: ='Data Sheet'!G57/'Data Sheet'!G$61 -> 0.0041150383 | E30: ='Data Sheet'!H57/'Data Sheet'!H$61 -> 0.0027751995 | F30: ='Data Sheet'!I57/'Data Sheet'!I$61 -> 0.0025451818 | G30: ='Data Sheet'!J57/'Data Sheet'!J$61 -> 0.0017111308 | H30: ='Data Sheet'!K57/'Data Sheet'!K$61 -> 0.00071907028
B31: ='Data Sheet'!A58 -> Reserves | C31: ='Data Sheet'!F58/'Data Sheet'!F$61 -> 0.31218178 | D31: ='Data Sheet'!G58/'Data Sheet'!G$61 -> 0.25498127 | E31: ='Data Sheet'!H58/'Data Sheet'!H$61 -> 0.23027142 | F31: ='Data Sheet'!I58/'Data Sheet'!I$61 -> 0.27204168 | G31: ='Data Sheet'!J58/'Data Sheet'!J$61 -> 0.24077298 | H31: ='Data Sheet'!K58/'Data Sheet'!K$61 -> 0.17891125
B32: ='Data Sheet'!A59 -> Borrowings | C32: ='Data Sheet'!F59/'Data Sheet'!F$61 -> 0.051073685 | D32: ='Data Sheet'!G59/'Data Sheet'!G$61 -> 0.10350147 | E32: ='Data Sheet'!H59/'Data Sheet'!H$61 -> 0.15592085 | F32: ='Data Sheet'!I59/'Data Sheet'!I$61 -> 0.096825895 | G32: ='Data Sheet'!J59/'Data Sheet'!J$61 -> 0.069958924 | H32: ='Data Sheet'!K59/'Data Sheet'!K$61 -> 0.040038788
B33: ='Data Sheet'!A60 -> Other Liabilities | C33: ='Data Sheet'!F60/'Data Sheet'!F$61 -> 0.62992646 | D33: ='Data Sheet'!G60/'Data Sheet'!G$61 -> 0.63740222 | E33: ='Data Sheet'!H60/'Data Sheet'!H$61 -> 0.61103253 | F33: ='Data Sheet'!I60/'Data Sheet'!I$61 -> 0.62858724 | G33: ='Data Sheet'!J60/'Data Sheet'!J$61 -> 0.68755696 | H33: ='Data Sheet'!K60/'Data Sheet'!K$61 -> 0.78033089
B35: Total Assets | C35: ='Data Sheet'!F66/'Data Sheet'!F$61 -> 1 | D35: ='Data Sheet'!G66/'Data Sheet'!G$61 -> 1 | E35: ='Data Sheet'!H66/'Data Sheet'!H$61 -> 1 | F35: ='Data Sheet'!I66/'Data Sheet'!I$61 -> 1 | G35: ='Data Sheet'!J66/'Data Sheet'!J$61 -> 1 | H35: ='Data Sheet'!K66/'Data Sheet'!K$61 -> 1
B36: ='Data Sheet'!A62 -> Net Block | C36: ='Data Sheet'!F62/'Data Sheet'!F$61 -> 0.24401282 | D36: ='Data Sheet'!G62/'Data Sheet'!G$61 -> 0.1933576 | E36: ='Data Sheet'!H62/'Data Sheet'!H$61 -> 0.23456865 | F36: ='Data Sheet'!I62/'Data Sheet'!I$61 -> 0.26576741 | G36: ='Data Sheet'!J62/'Data Sheet'!J$61 -> 0.28560576 | H36: ='Data Sheet'!K62/'Data Sheet'!K$61 -> 0.16552103
B37: ='Data Sheet'!A63 -> Capital Work in Progress | C37: ='Data Sheet'!F63/'Data Sheet'!F$61 -> 0.0056277107 | D37: ='Data Sheet'!G63/'Data Sheet'!G$61 -> 0.025438738 | E37: ='Data Sheet'!H63/'Data Sheet'!H$61 -> 0.0052347697 | F37: ='Data Sheet'!I63/'Data Sheet'!I$61 -> 0.025580039 | G37: ='Data Sheet'!J63/'Data Sheet'!J$61 -> 0.0097774815 | H37: ='Data Sheet'!K63/'Data Sheet'!K$61 -> 0.015333204
B38: ='Data Sheet'!A64 -> Investments | C38: ='Data Sheet'!F64/'Data Sheet'!F$61 -> 0 | D38: ='Data Sheet'!G64/'Data Sheet'!G$61 -> 0.033472024 | E38: ='Data Sheet'!H64/'Data Sheet'!H$61 -> 0.032956371 | F38: ='Data Sheet'!I64/'Data Sheet'!I$61 -> 0.0094349098 | G38: ='Data Sheet'!J64/'Data Sheet'!J$61 -> 0.0028671456 | H38: ='Data Sheet'!K64/'Data Sheet'!K$61 -> 0.031961331
B39: ='Data Sheet'!A67 -> Receivables | C39: ='Data Sheet'!F67/'Data Sheet'!F$66 -> 0.30355459 | D39: ='Data Sheet'!G67/'Data Sheet'!G$66 -> 0.38270911 | E39: ='Data Sheet'!H67/'Data Sheet'!H$66 -> 0.31711389 | F39: ='Data Sheet'!I67/'Data Sheet'!I$66 -> 0.36659379 | G39: ='Data Sheet'!J67/'Data Sheet'!J$66 -> 0.33162173 | H39: ='Data Sheet'!K67/'Data Sheet'!K$66 -> 0.41565544
B40: ='Data Sheet'!A68 -> Inventory | C40: ='Data Sheet'!F68/'Data Sheet'!F$66 -> 0.29337168 | D40: ='Data Sheet'!G68/'Data Sheet'!G$66 -> 0.26118721 | E40: ='Data Sheet'!H68/'Data Sheet'!H$66 -> 0.27019969 | F40: ='Data Sheet'!I68/'Data Sheet'!I$66 -> 0.20469801 | G40: ='Data Sheet'!J68/'Data Sheet'!J$66 -> 0.24250701 | H40: ='Data Sheet'!K68/'Data Sheet'!K$66 -> 0.23824201
B41: ='Data Sheet'!A69 -> Cash & Bank | C41: ='Data Sheet'!F69/'Data Sheet'!F$66 -> 0.059023194 | D41: ='Data Sheet'!G69/'Data Sheet'!G$66 -> 0.024205281 | E41: ='Data Sheet'!H69/'Data Sheet'!H$66 -> 0.042630992 | F41: ='Data Sheet'!I69/'Data Sheet'!I$66 -> 0.048976051 | G41: ='Data Sheet'!J69/'Data Sheet'!J$66 -> 0.029851793 | H41: ='Data Sheet'!K69/'Data Sheet'!K$66 -> 0.015725858
B42: Other Assets | C42: =('Data Sheet'!F65-SUM('Data Sheet'!F67:F69))/'Data Sheet'!F$66 -> 0.094410004 | D42: =('Data Sheet'!G65-SUM('Data Sheet'!G67:G69))/'Data Sheet'!G$66 -> 0.079630033 | E42: =('Data Sheet'!H65-SUM('Data Sheet'!H67:H69))/'Data Sheet'!H$66 -> 0.097295642 | F42: =('Data Sheet'!I65-SUM('Data Sheet'!I67:I69))/'Data Sheet'!I$66 -> 0.078949787 | G42: =('Data Sheet'!J65-SUM('Data Sheet'!J67:J69))/'Data Sheet'!J$66 -> 0.097769092 | H42: =('Data Sheet'!K65-SUM('Data Sheet'!K67:K69))/'Data Sheet'!K$66 -> 0.11756113

Sheet Forecasting
A2: # | B2: ='Data Sheet'!$B$1 & "- Sales Forecasting" -> DIXON TECHNOLOGIES (INDIA) LTD- Sales Forecasting
B3: Year | C3: Sales | D3: Sales Growth
B4: 2020 | C4: 4400.12 | J4: Revenue Growth Assumptions
B5: =B4+1 -> 2021 | C5: 6448.17 | D5: =(C5/C4)-1 -> 0.46545321 | J5: 2026 | K5: =Assumptions!C5 -> 0.25
B6: =B5+1 -> 2022 | C6: 10697.08 | D6: =(C6/C5)-1 -> 0.65893269 | J6: 2027 | K6: =Assumptions!D5 -> 0.22
B7: =B6+1 -> 2023 | C7: 12192.01 | D7: =(C7/C6)-1 -> 0.13975122 | J7: 2028 | K7: =Assumptions!E5 -> 0.15
B8: =B7+1 -> 2024 | C8: 17690.9 | D8: =(C8/C7)-1 -> 0.45102407 | J8: 2029 | K8: =Assumptions!F5 -> 0.18
B9: =B8+1 -> 2025 | C9: 38860.1 | D9: =(C9/C8)-1 -> 1.1966152 | J9: 2030 | K9: =Assumptions!G5 -> 0.12
B10: =B9+1 -> 2026 | C10: =C9+(C9*K5) -> 48575.125 | D10: =K5 -> 0.25
B11: =B10+1 -> 2027 | C11: =C10+(C10*K6) -> 59261.652 | D11: =K6 -> 0.22
B12: =B11+1 -> 2028 | C12: =C11+(C11*K7) -> 68150.9 | D12: =K7 -> 0.15
B13: =B12+1 -> 2029 | C13: =C12+(C12*K8) -> 80418.062 | D13: =K8 -> 0.18 | J13: Tax Rate | K13: =Assumptions!C10 -> 0.25
B14: =B13+1 -> 2030 | C14: =C13+(C13*K9) -> 90068.23 | D14: =K9 -> 0.12
A16: # | B16: ='Data Sheet'!$B$1 & "- EBITDA Forecasting" -> DIXON TECHNOLOGIES (INDIA) LTD- EBITDA Forecasting
B17: Year | C17: EBITDA % | D17: EBITDA | E17: Depreciation | F17: EBIT | G17: NOPAT | J17: Assumptions
B18: 2020 | C18: 0.051778133 | D18: =C4*C18 -> 227.83 | E18: =HistoricalFS!C25 -> 36.53 | F18: =D18-E18 -> 191.3 | G18: =F18*(1-$K$13) -> 143.475 | K18: EBITDA% | L18: Depreciation %
B19: =B18+1 -> 2021 | C19: 0.045315182 | D19: =C5*C19 -> 292.2 | E19: =HistoricalFS!D25 -> 43.72 | F19: =D19-E19 -> 248.48 | G19: =F19*(1-$K$13) -> 186.36 | J19: 2026 | K19: =Assumptions!C8 -> 0.045 | L19: =Assumptions!$C$12 -> 0.008
B20: =B19+1 -> 2022 | C20: 0.035925692 | D20: =C6*C20 -> 384.3 | E20: =HistoricalFS!E25 -> 83.95 | F20: =D20-E20 -> 300.35 | G20: =F20*(1-$K$13) -> 225.2625 | J20: 2027 | K20: =Assumptions!D8 -> 0.05 | L20: =Assumptions!$D$12 -> 0.008
B21: =B20+1 -> 2023 | C21: 0.042605772 | D21: =C7*C21 -> 519.45 | E21: =HistoricalFS!F25 -> 114.63 | F21: =D21-E21 -> 404.82 | G21: =F21*(1-$K$13) -> 303.615 | J21: 2028 | K21: =Assumptions!E8 -> 0.059 | L21: =Assumptions!$E$12 -> 0.008
B22: =B21+1 -> 2024 | C22: 0.039853823 | D22: =C8*C22 -> 705.05 | E22: =HistoricalFS!G25 -> 161.88 | F22: =D22-E22 -> 543.17 | G22: =F22*(1-$K$13) -> 407.3775 | J22: 2029 | K22: =Assumptions!F8 -> 0.068 | L22: =Assumptions!$F$12 -> 0.008
B23: =B22+1 -> 2025 | C23: 0.038982144 | D23: =C9*C23 -> 1514.85 | E23: =HistoricalFS!H25 -> 281.02 | F23: =D23-E23 -> 1233.83 | G23: =F23*(1-$K$13) -> 925.3725 | J23: 2030 | K23: =Assumptions!G8 -> 0.075 | L23: =Assumptions!$G$12 -> 0.008
B24: =B23+1 -> 2026 | C24: =K19 -> 0.045 | D24: =C10*C24 -> 2185.8806 | E24: =C10*L19 -> 388.601 | F24: =D24-E24 -> 1797.2796 | G24: =F24*(1-$K$13) -> 1347.9597
B25: =B24+1 -> 2027 | C25: =K20 -> 0.05 | D25: =C11*C25 -> 2963.0826 | E25: =C11*L20 -> 474.09322 | F25: =D25-E25 -> 2488.9894 | G25: =F25*(1-$K$13) -> 1866.7421
B26: =B25+1 -> 2028 | C26: =K21 -> 0.059 | D26: =C12*C26 -> 4020.9031 | E26: =C12*L21 -> 545.2072 | F26: =D26-E26 -> 3475.6959 | G26: =F26*(1-$K$13) -> 2606.7719
B27: =B26+1 -> 2029 | C27: =K22 -> 0.068 | D27: =C13*C27 -> 5468.4282 | E27: =C13*L22 -> 643.3445 | F27: =D27-E27 -> 4825.0837 | G27: =F27*(1-$K$13) -> 3618.8128
B28: =B27+1 -> 2030 | C28: =K23 -> 0.075 | D28: =C14*C28 -> 6755.1172 | E28: =C14*L23 -> 720.54584 | F28: =D28-E28 -> 6034.5714 | G28: =F28*(1-$K$13) -> 4525.9286

Sheet WC
B4: Working Capital Projections | N4: Assumptions
B5: Year | C5: Revenue | D5: Receivables | E5: Inventory | F5: COGS | G5: Receivable Days | H5: Inventory Days | I5: Δ Receivables | J5: Δ Inventory | K5: Total WC Change | N5: Year | O5: Receivable Days | P5: Inventory Days | Q5: COGS
B6: {=TRANSPOSE(YEAR(HistoricalFS!C3:H3))} -> 2020 | C6: {=TRANSPOSE(HistoricalFS!C6:H6)} -> 4400.12 | D6: {=TRANSPOSE(HistoricalFS!C63:H63)} -> 515.12 | E6: {=TRANSPOSE(HistoricalFS!C64:H64)} -> 497.84 | F6: {=TRANSPOSE(HistoricalFS!C9:H9)} -> 4119.71 | G6: =D6/C6*365 -> 42.73038 | H6: =E6/F6*365 -> 44.107862 | N6: 2026 | O6: =Assumptions!$C$15 -> 57 | P6: =Assumptions!$C$16 -> 39 | Q6: =Assumptions!C6 -> 0.952
B7: 2021 | C7: 6448.17 | D7: 1089.06 | E7: 743.25 | F7: 6082.95 | G7: =D7/C7*365 -> 61.646467 | H7: =E7/F7*365 -> 44.59781 | I7: =D7-D6 -> 573.94 | J7: =E7-E6 -> 245.41 | K7: =J7+I7 -> 819.35 | N7: 2027 | O7: =Assumptions!$D$15 -> 54 | P7: =Assumptions!$D$16 -> 39 | Q7: =Assumptions!D6 -> 0.95
B8: 2022 | C8: 10697.08 | D8: 1356.35 | E8: 1155.69 | F8: 10225.37 | G8: =D8/C8*365 -> 46.280644 | H8: =E8/F8*365 -> 41.252967 | I8: =D8-D7 -> 267.29 | J8: =E8-E7 -> 412.44 | K8: =J8+I8 -> 679.73 | N8: 2028 | O8: =Assumptions!$E$15 -> 50 | P8: =Assumptions!$E$16 -> 38 | Q8: =Assumptions!E6 -> 0.948
B9: 2023 | C9: 12192.01 | D9: 1715.45 | E9: 957.87 | F9: 11566.32 | G9: =D9/C9*365 -> 51.356524 | H9: =E9/F9*365 -> 30.227639 | I9: =D9-D8 -> 359.1 | J9: =E9-E8 -> -197.82 | K9: =J9+I9 -> 161.28 | N9: 2029 | O9: =Assumptions!$F$15 -> 47 | P9: =Assumptions!$F$16 -> 38 | Q9: =Assumptions!F6 -> 0.947
B10: 2024 | C10: 17690.9 | D10: 2317.88 | E10: 1695.01 | F10: 16854.72 | G10: =D10/C10*365 -> 47.822677 | H10: =E10/F10*365 -> 36.706552 | I10: =D10-D9 -> 602.43 | J10: =E10-E9 -> 737.14 | K10: =J10+I10 -> 1339.57 | N10: 2030 | O10: =Assumptions!$G$15 -> 44 | P10: =Assumptions!$G$16 -> 38 | Q10: =Assumptions!G6 -> 0.945
B11: 2025 | C11: 38860.1 | D11: 6965.45 | E11: 3992.4 | F11: 37116.31 | G11: =D11/C11*365 -> 65.424156 | H11: =E11/F11*365 -> 39.261069 | I11: =D11-D10 -> 4647.57 | J11: =E11-E10 -> 2297.39 | K11: =J11+I11 -> 6944.96
B12: =B11+1 -> 2026 | C12: =Forecasting!C10 -> 48575.125 | D12: =(O6/365)*C12 -> 7585.7045 | E12: =(P6/365)*F12 -> 4941.0883 | F12: =C12*Q6 -> 46243.519 | G12: =Assumptions!C15 -> 57 | H12: =Assumptions!C16 -> 39 | I12: =D12-D11 -> 620.25445 | J12: =E12-E11 -> 948.68833 | K12: =J12+I12 -> 1568.9428
B13: =B12+1 -> 2027 | C13: =Forecasting!C11 -> 59261.652 | D13: =(O7/365)*C13 -> 8767.4774 | E13: =(P7/365)*F13 -> 6015.4636 | F13: =C13*Q7 -> 56298.57 | G13: =Assumptions!D15 -> 54 | H13: =Assumptions!D16 -> 39 | I13: =D13-D12 -> 1181.7729 | J13: =E13-E12 -> 1074.3753 | K13: =J13+I13 -> 2256.1482
B14: =B13+1 -> 2028 | C14: =Forecasting!C12 -> 68150.9 | D14: =(O8/365)*C14 -> 9335.7398 | E14: =(P8/365)*F14 -> 6726.2138 | F14: =C14*Q8 -> 64607.054 | G14: =Assumptions!E15 -> 50 | H14: =Assumptions!E16 -> 38 | I14: =D14-D13 -> 568.26242 | J14: =E14-E13 -> 710.75016 | K14: =J14+I14 -> 1279.0126
B15: =B14+1 -> 2029 | C15: =Forecasting!C13 -> 80418.062 | D15: =(O9/365)*C15 -> 10355.203 | E15: =(P9/365)*F15 -> 7928.56 | F15: =C15*Q9 -> 76155.905 | G15: =Assumptions!F15 -> 47 | H15: =Assumptions!F16 -> 38 | I15: =D15-D14 -> 1019.4628 | J15: =E15-E14 -> 1202.3462 | K15: =J15+I15 -> 2221.809
B16: =B15+1 -> 2030 | C16: =Forecasting!C14 -> 90068.23 | D16: =(O10/365)*C16 -> 10857.54 | E16: =(P10/365)*F16 -> 8861.2333 | F16: =C16*Q10 -> 85114.477 | G16: =Assumptions!G15 -> 44 | H16: =Assumptions!G16 -> 38 | I16: =D16-D15 -> 502.33749 | J16: =E16-E15 -> 932.67327 | K16: =J16+I16 -> 1435.0108

Sheet Projected CFS
A3: # | B3: Cash Flow from Operating Activities | I3: Assumption
B4: Year | C4: NOPAT | D4: Depreciation | E4: Δ WC | F4: CFO | J4: Tax Rate | K4: Dep % | L4: Capex %
B5: =Forecasting!B18 -> 2020 | C5: =Forecasting!G18 -> 143.475 | D5: =Forecasting!E18 -> 36.53 | E5: =WC!K6 -> 0 | F5: =C5+D5-E5 -> 180.005 | I5: =B11 -> 2026 | J5: =Assumptions!C10 -> 0.25 | K5: =Assumptions!C12 -> 0.008 | L5: =Assumptions!C13 -> 0.02
B6: =Forecasting!B19 -> 2021 | C6: =Forecasting!G19 -> 186.36 | D6: =Forecasting!E19 -> 43.72 | E6: =WC!K7 -> 819.35 | F6: =C6+D6-E6 -> -589.27 | I6: =B12 -> 2027 | J6: =Assumptions!D10 -> 0.25 | K6: =Assumptions!D12 -> 0.008 | L6: =Assumptions!D13 -> 0.018
B7: =Forecasting!B20 -> 2022 | C7: =Forecasting!G20 -> 225.2625 | D7: =Forecasting!E20 -> 83.95 | E7: =WC!K8 -> 679.73 | F7: =C7+D7-E7 -> -370.5175 | I7: =B13 -> 2028 | J7: =Assumptions!E10 -> 0.25 | K7: =Assumptions!E12 -> 0.008 | L7: =Assumptions!E13 -> 0.015
B8: =Forecasting!B21 -> 2023 | C8: =Forecasting!G21 -> 303.615 | D8: =Forecasting!E21 -> 114.63 | E8: =WC!K9 -> 161.28 | F8: =C8+D8-E8 -> 256.965 | I8: =B14 -> 2029 | J8: =Assumptions!F10 -> 0.25 | K8: =Assumptions!F12 -> 0.008 | L8: =Assumptions!F13 -> 0.013
B9: =Forecasting!B22 -> 2024 | C9: =Forecasting!G22 -> 407.3775 | D9: =Forecasting!E22 -> 161.88 | E9: =WC!K10 -> 1339.57 | F9: =C9+D9-E9 -> -770.3125 | I9: =B15 -> 2030 | J9: =Assumptions!G10 -> 0.25 | K9: =Assumptions!G12 -> 0.008 | L9: =Assumptions!G13 -> 0.012
B10: =Forecasting!B23 -> 2025 | C10: =Forecasting!G23 -> 925.3725 | D10: =Forecasting!E23 -> 281.02 | E10: =WC!K11 -> 6944.96 | F10: =C10+D10-E10 -> -5738.5675
B11: =Forecasting!B24 -> 2026 | C11: =Forecasting!G24 -> 1347.9597 | D11: =Forecasting!E24 -> 388.601 | E11: =WC!K12 -> 1568.9428 | F11: =C11+D11-E11 -> 167.61794
B12: =Forecasting!B25 -> 2027 | C12: =Forecasting!G25 -> 1866.7421 | D12: =Forecasting!E25 -> 474.09322 | E12: =WC!K13 -> 2256.1482 | F12: =C12+D12-E12 -> 84.687071
B13: =Forecasting!B26 -> 2028 | C13: =Forecasting!G26 -> 2606.7719 | D13: =Forecasting!E26 -> 545.2072 | E13: =WC!K14 -> 1279.0126 | F13: =C13+D13-E13 -> 1872.9666
B14: =Forecasting!B27 -> 2029 | C14: =Forecasting!G27 -> 3618.8128 | D14: =Forecasting!E27 -> 643.3445 | E14: =WC!K15 -> 2221.809 | F14: =C14+D14-E14 -> 2040.3483
B15: =Forecasting!B28 -> 2030 | C15: =Forecasting!G28 -> 4525.9286 | D15: =Forecasting!E28 -> 720.54584 | E15: =WC!K16 -> 1435.0108 | F15: =C15+D15-E15 -> 3811.4636
A17: # | B17: Capex and Depreciation
B18: Year | C18: Revenue | D18: Dep % | E18: Depreciation | F18: Capex % | G18: Capex
B19: =Forecasting!B10 -> 2026 | C19: =Forecasting!C10 -> 48575.125 | D19: =K5 -> 0.008 | E19: =C19*D19 -> 388.601 | F19: =L5 -> 0.02 | G19: =C19*F19 -> 971.5025
B20: =Forecasting!B11 -> 2027 | C20: =Forecasting!C11 -> 59261.652 | D20: =K6 -> 0.008 | E20: =C20*D20 -> 474.09322 | F20: =L6 -> 0.018 | G20: =C20*F20 -> 1066.7097
B21: =Forecasting!B12 -> 2028 | C21: =Forecasting!C12 -> 68150.9 | D21: =K7 -> 0.008 | E21: =C21*D21 -> 545.2072 | F21: =L7 -> 0.015 | G21: =C21*F21 -> 1022.2635
B22: =Forecasting!B13 -> 2029 | C22: =Forecasting!C13 -> 80418.062 | D22: =K8 -> 0.008 | E22: =C22*D22 -> 643.3445 | F22: =L8 -> 0.013 | G22: =C22*F22 -> 1045.4348
B23: =Forecasting!B14 -> 2030 | C23: =Forecasting!C14 -> 90068.23 | D23: =K9 -> 0.008 | E23: =C23*D23 -> 720.54584 | F23: =L9 -> 0.012 | G23: =C23*F23 -> 1080.8188
A25: # | B25: FCFF Unlevered
B26: Year | C26: CFO | D26: Capex | E26: FCF
B27: =B19 -> 2026 | C27: =F11 -> 167.61794 | D27: =G19 -> 971.5025 | E27: =C27-D27 -> -803.88456
B28: =B20 -> 2027 | C28: =F12 -> 84.687071 | D28: =G20 -> 1066.7097 | E28: =C28-D28 -> -982.02267
B29: =B21 -> 2028 | C29: =F13 -> 1872.9666 | D29: =G21 -> 1022.2635 | E29: =C29-D29 -> 850.70305
B30: =B22 -> 2029 | C30: =F14 -> 2040.3483 | D30: =G22 -> 1045.4348 | E30: =C30-D30 -> 994.91352
B31: =B23 -> 2030 | C31: =F15 -> 3811.4636 | D31: =G23 -> 1080.8188 | E31: =C31-D31 -> 2730.6449

Sheet DCF
A3: # | B3: Discounted Cash Flow
B4: Year | C4: N | D4: Future Cash Flow | E4: Discounting Factor | F4: Present Value | J4: Assumption
B5: =Forecasting!B10 -> 2026 | C5: 1 | D5: ='Projected CFS'!E27 -> -803.88456 | E5: =1/(1+DCF!$K$5)^C5 -> 0.88912599 | F5: =D5*E5 -> -714.75466 | J5: WACC | K5: =Assumptions!C27 -> 0.1247
B6: =Forecasting!B11 -> 2027 | C6: 2 | D6: ='Projected CFS'!E28 -> -982.02267 | E6: =1/(1+DCF!$K$5)^C6 -> 0.79054502 | F6: =D6*E6 -> -776.33314 | J6: Terminal Growth | K6: =Assumptions!C29 -> 0.06
B7: =Forecasting!B12 -> 2028 | C7: 3 | D7: ='Projected CFS'!E29 -> 850.70305 | E7: =1/(1+DCF!$K$5)^C7 -> 0.70289413 | F7: =D7*E7 -> 597.95418
B8: =Forecasting!B13 -> 2029 | C8: 4 | D8: ='Projected CFS'!E30 -> 994.91352 | E8: =1/(1+DCF!$K$5)^C8 -> 0.62496144 | F8: =D8*E8 -> 621.78258 | J8: Terminal Value | K8: =(D9*(1+DCF!K6))/(DCF!K5-DCF!K6) -> 44736.995
B9: =Forecasting!B14 -> 2030 | C9: 5 | D9: ='Projected CFS'!E31 -> 2730.6449 | E9: =1/(1+DCF!$K$5)^C9 -> 0.55566945 | F9: =D9*E9 -> 1517.336
B10: TV | C10: 5 | D10: =K8 -> 44736.995 | E10: =1/(1+DCF!$K$5)^C10 -> 0.55566945 | F10: =D10*E10 -> 24858.982
D12: Enterprise Value | F12: =SUM(F5:F10) -> 26104.967
A16: # | D16: Valuation Summary | G16: DCF Sensitivity (Implied Share Price - ₹ Per Share)
D17: Metric | E17: Value | G17: Current Market Price = 10334.3 | I17: WACC (%)
D18: Enterprise Value (Cr) | E18: =F12 -> 26104.967 | G18: Terminal Growth (%) | H18: =E23 -> 4268.6938 | I18: 0.115 | J18: 0.12 | K18: 0.125 | L18: 0.13 | M18: 0.135
D19: Net Debt (Cr) | E19: =HistoricalFS!H53-HistoricalFS!H65 -> 407.43 | H19: 0.05 | I19: 4405.1963 | J19: 4006.7795 | K19: 3662.8557 | L19: 3363.1768 | M19: 3099.907 | P19: Scenario | Q19: WACC | R19: g | S19: Price
D20: Equity Value (Cr) | E20: =E18-E19 -> 25697.537 | H20: 0.055 | I20: 4781.4447 | J20: 4323.5577 | K20: 3932.5485 | L20: 3595.009 | M20: 3300.884 | P20: Bear | Q20: =M18 -> 0.135 | R20: =H19 -> 0.05 | S20: =M19 -> 3099.907
D21: Shares Outstanding (Cr) | E21: =HistoricalFS!H37 -> 6.02 | H21: 0.06 | I21: 5226.1019 | J21: 4693.1322 | K21: 4243.7325 | L21: 3859.9601 | M21: 3528.658 | P21: Base | Q21: =K18 -> 0.125 | R21: =H21 -> 0.06 | S21: =K21 -> 4243.7325
H22: 0.065 | I22: 5759.6906 | J22: 5129.9021 | K22: 4606.7804 | L22: 4165.6728 | M22: 3788.9711 | P22: Bull | Q22: =I18 -> 0.115 | R22: =H23 -> 0.07 | S22: =I23 -> 6411.8545
D23: Implied Share Price | E23: =E20/E21 -> 4268.6938 | H23: 0.07 | I23: 6411.8545 | J23: 5654.026 | K23: 5035.8372 | L23: 4522.3377 | M23: 4089.3323
D24: Current Price | E24: ='Data Sheet'!B8 -> 10334.3
D26: Upside/Downside (%) | E26: =(E23-E24)/E24 -> -0.58693924
D28: EV/EBITDA | E28: =K8/Forecasting!D28 -> 6.6226822

Sheet Data Sheet
A1: COMPANY NAME | B1: DIXON TECHNOLOGIES (INDIA) LTD | E1: =IF(B2<>B3, "A NEW VERSION OF THE WORKSHEET IS AVAILABLE", "")
A2: LATEST VERSION | B2: 2.1 | E2: PLEASE DO NOT MAKE ANY CHANGES TO THIS SHEET
A3: CURRENT VERSION | B3: 2.1
A5: META
A6: Number of shares | B6: =IF(B9>0, B9/B8, 0) -> 6.0797422
A7: Face Value | B7: 2
A8: Current Price | B8: 10334.3
A9: Market Capitalization | B9: 62829.88
A15: PROFIT & LOSS | B15: =B26+B34 -> 80.59 | K15: =K17-K18-K20-K21-K22-K23-K19 -> 1139.41
A16: Report Date | B16: 42460 | C16: 42825 | D16: 43190 | E16: 43555 | F16: 43921 | G16: 44286 | H16: 44651 | I16: 45016 | J16: 45382 | K16: 45747
A17: Sales | B17: 1389.42 | C17: 2457.03 | D17: 2841.63 | E17: 2984.45 | F17: 4400.12 | G17: 6448.17 | H17: 10697.08 | I17: 12192.01 | J17: 17690.9 | K17: 38860.1
A18: Raw Material Cost | B18: 1228.44 | C18: 2205.61 | D18: 2545.36 | E18: 2594.61 | F18: 3913.34 | G18: 5753.41 | H18: 9889.66 | I18: 11015.17 | J18: 16142.42 | K18: 36099.81
A19: Change in Inventory | B19: 16.13 | C19: 25.53 | D19: 34.98 | E19: -14.66 | F19: 53.14 | G19: -16.31 | H19: 110.42 | I19: -5.57 | J19: 103.47 | K19: 266.99
A20: Power and Fuel | B20: 8.68 | C20: 10.97 | D20: 14.47 | E20: 18.38 | F20: 22.2 | G20: 26.39 | H20: 40.41 | I20: 47.33 | J20: 65.79 | K20: 102.15
A21: Other Mfr. Exp | B21: 35.95 | C21: 76.38 | D21: 96.65 | E21: 90.4 | F21: 119.35 | G21: 149.64 | H21: 207.65 | I21: 246.31 | J21: 417.12 | K21: 613.49
A22: Employee Cost | B22: 54.96 | C22: 63.91 | D22: 72.75 | E22: 83.87 | F22: 117.96 | G22: 137.2 | H22: 198.07 | I22: 251.94 | J22: 332.86 | K22: 567.85
A23: Selling and admin | B23: 7.67 | C23: 20.27 | D23: 18.72 | E23: 24.82 | F23: 22.98 | G23: 36.89 | H23: 45.57 | I23: 50.32 | J23: 54.75 | K23: 70.4
A24: Other Expenses | B24: 20.53 | C24: 13.64 | D24: 15.78 | E24: 21.55 | F24: 29.6 | G24: 36.13 | H24: 41.84 | I24: 55.92 | J24: 76.38 | K24: 158.54
A25: Other Income | B25: 22.83 | C25: 0.86 | D25: 3.98 | E25: 5.63 | F25: 4.9 | G25: 1.25 | H25: 3.76 | I25: 4.03 | J25: 31.62 | K25: 497.49
A26: Depreciation | B26: 8.44 | C26: 10.71 | D26: 15.18 | E26: 21.65 | F26: 36.53 | G26: 43.72 | H26: 83.95 | I26: 114.63 | J26: 161.88 | K26: 281.02
A27: Interest | B27: 13.11 | C27: 15.54 | D27: 13.45 | E27: 26.32 | F27: 39.44 | G27: 32.72 | H27: 49.4 | I27: 64.07 | J27: 80.96 | K27: 161.52
... A31: Dividend Amount | B31: 3.88 | C31: 6.59 | D31: 2.27 | E31: 2.27 | F31: 4.63 | G31: 5.86 | H31: 11.87 | I31: 17.86 | J31: 29.9 | K31: 48.2
A32: Effective Tax Rate | B32: =B29/B28 -> 0.15869565 | C32: =C29/C28 -> 0.28347643 | D32: =D29/D28 -> 0.30975859 | E32: =E29/E28 -> 0.32466425 | F32: =F29/F28 -> 0.2313728 | G32: =G29/G28 -> 0.2636284 | H32: =H29/H28 -> 0.25275804 | I32: =I29/I28 -> 0.2601659 | ... K32: =K29/K28 -> 0.21481717
A34: EBITDA | B34: =+B30+B29+B27+B26 -> 72.15 | C34: =+C30+C29+C27+C26 -> 92.64 | D34: =+D30+D29+D27+D26 -> 116.86 | E34: =+E30+E29+E27+E26 -> 141.79 | F34: =+F30+F29+F27+F26 -> 232.74 | G34: =+G30+G29+G27+G26 -> 293.45 | H34: =+H30+H29+H27+H26 -> 387.9 | I34: =+I30+I29+I27+I26 -> 523.92 | ... K34: =+K30+K29+K27+K26 -> 1875.3
A40: Quarters
A41: Report Date | B41: 45199 | C41: 45291 | D41: 45382 | E41: 45473 | F41: 45565 | G41: 45657 | H41: 45747 | I41: 45838 | J41: 45930 | K41: 46022
A42: Sales | B42: 4943.18 | C42: 4818.25 | D42: 4657.97 | E42: 6579.8 | F42: 11534.08 | G42: 10453.68 | H42: 10292.54 | I42: 12835.66 | J42: 14855.04 | K42: 10671.59
A43: Expenses | B43: 4744.27 | C43: 4633.86 | D43: 4475.52 | E43: 6331.9 | F43: 11107.71 | G43: 10063.16 | H43: 9849.75 | I43: 12353.29 | J43: 14293.71 | K43: 10257.14
A44: Other Income | B44: 3.19 | C44: 4.25 | D44: 19.49 | E44: 15.62 | F44: 206.48 | G44: 10.08 | H44: 265.41 | I44: 8.44 | J44: 496.89 | K44: 139.14
A45: Depreciation | B45: 36.44 | C45: 40.7 | D45: 51.03 | E45: 54.51 | F45: 66 | G45: 74.6 | H45: 85.91 | I45: 92.7 | J45: 96.28 | K45: 99.03
A46: Interest | B46: 17.12 | C46: 22.2 | D46: 21.4 | E46: 29.29 | F46: 37.93 | G46: 40.87 | H46: 46.26 | I46: 32.59 | J46: 38.35 | K46: 42.87
A47: Profit before tax | B47: 148.54 | C47: 125.74 | D47: 129.51 | E47: 179.72 | F47: 528.92 | G47: 285.13 | H47: 576.03 | I47: 365.52 | J47: 923.59 | K47: 411.69
A48: Tax | B48: 35.18 | C48: 28.67 | D48: 32.21 | E48: 40.02 | F48: 117.22 | G48: 68.9 | H48: 111.08 | I48: 85.5 | J48: 177.89 | K48: 91.13
A49: Net profit | B49: 107.32 | C49: 96.44 | D49: 95.17 | E49: 133.68 | F49: 389.85 | G49: 171.19 | H49: 400.82 | I49: 224.97 | J49: 670 | K49: 287.26
A50: Operating Profit | B50: 198.91 | C50: 184.39 | D50: 182.45 | E50: 247.9 | F50: 426.37 | G50: 390.52 | H50: 442.79 | I50: 482.37 | J50: 561.33 | K50: 414.45
A51: EBITDA | B51: =B49+B48+B46+B45 -> 196.06 | C51: =C49+C48+C46+C45 -> 188.01 | D51: =D49+D48+D46+D45 -> 199.81 | E51: =E49+E48+E46+E45 -> 257.5 | F51: =F49+F48+F46+F45 -> 611 | G51: =G49+G48+G46+G45 -> 355.56 | H51: =H49+H48+H46+H45 -> 644.07 | I51: =I49+I48+I46+I45 -> 435.76 | ... K51: =K49+K48+K46+K45 -> 520.29
A55: BALANCE SHEET
A56: Report Date | B56: 42460 | C56: 42825 | D56: 43190 | E56: 43555 | F56: 43921 | G56: 44286 | H56: 44651 | I56: 45016 | J56: 45382 | K56: 45747
A57: Equity Share Capital | B57: 3.1 | C57: 10.99 | D57: 11.33 | E57: 11.33 | F57: 11.57 | G57: 11.71 | H57: 11.87 | I57: 11.91 | J57: 11.96 | K57: 12.05
A58: Reserves | B58: 119.71 | C58: 186.08 | D58: 303.65 | E58: 366.89 | F58: 529.76 | G58: 725.59 | H58: 984.91 | I58: 1273 | J58: 1682.89 | K58: 2998.15
...
